2024-10-29 18:19:50,999 - INFO - Starting pipeline execution
2024-10-29 18:19:50,999 - INFO - Starting step: initialize_database
2024-10-29 18:19:51,012 - ERROR - Error in step initialize_database: cannot access local variable 'tag_status' where it is not associated with a value
Traceback (most recent call last):
  File "C:\Users\mmenaarx\Project_AI_CoE\ai-demo-sync-utils-main\main.py", line 116, in wrapper
    result = func(self, *args, **kwargs)
             ^^^^^^^^^^^^^^^^^^^^^^^^^^^
  File "C:\Users\mmenaarx\Project_AI_CoE\ai-demo-sync-utils-main\main.py", line 132, in initialize_database
    db_status = db_instance.database_creation()
                ^^^^^^^^^^^^^^^^^^^^^^^^^^^^^^^
  File "C:\Users\mmenaarx\Project_AI_CoE\ai-demo-sync-utils-main\database\database_schema.py", line 68, in database_creation
    return db_status and tag_status
                         ^^^^^^^^^^
UnboundLocalError: cannot access local variable 'tag_status' where it is not associated with a value
2024-10-29 18:19:51,025 - ERROR - Pipeline failed with error:
Traceback (most recent call last):
  File "C:\Users\mmenaarx\Project_AI_CoE\ai-demo-sync-utils-main\main.py", line 185, in run_pipeline
    self.initialize_database()
  File "C:\Users\mmenaarx\Project_AI_CoE\ai-demo-sync-utils-main\main.py", line 116, in wrapper
    result = func(self, *args, **kwargs)
             ^^^^^^^^^^^^^^^^^^^^^^^^^^^
  File "C:\Users\mmenaarx\Project_AI_CoE\ai-demo-sync-utils-main\main.py", line 132, in initialize_database
    db_status = db_instance.database_creation()
                ^^^^^^^^^^^^^^^^^^^^^^^^^^^^^^^
  File "C:\Users\mmenaarx\Project_AI_CoE\ai-demo-sync-utils-main\database\database_schema.py", line 68, in database_creation
    return db_status and tag_status
                         ^^^^^^^^^^
UnboundLocalError: cannot access local variable 'tag_status' where it is not associated with a value
2024-10-29 18:19:51,025 - ERROR - Pipeline execution failed
Traceback (most recent call last):
  File "C:\Users\mmenaarx\Project_AI_CoE\ai-demo-sync-utils-main\main.py", line 205, in <module>
    pipeline.run_pipeline()
  File "C:\Users\mmenaarx\Project_AI_CoE\ai-demo-sync-utils-main\main.py", line 185, in run_pipeline
    self.initialize_database()
  File "C:\Users\mmenaarx\Project_AI_CoE\ai-demo-sync-utils-main\main.py", line 116, in wrapper
    result = func(self, *args, **kwargs)
             ^^^^^^^^^^^^^^^^^^^^^^^^^^^
  File "C:\Users\mmenaarx\Project_AI_CoE\ai-demo-sync-utils-main\main.py", line 132, in initialize_database
    db_status = db_instance.database_creation()
                ^^^^^^^^^^^^^^^^^^^^^^^^^^^^^^^
  File "C:\Users\mmenaarx\Project_AI_CoE\ai-demo-sync-utils-main\database\database_schema.py", line 68, in database_creation
    return db_status and tag_status
                         ^^^^^^^^^^
UnboundLocalError: cannot access local variable 'tag_status' where it is not associated with a value
