2024-10-29 18:27:09,204 - INFO - Starting pipeline execution
2024-10-29 18:27:09,205 - INFO - Starting step: initialize_database
2024-10-29 18:27:09,206 - ERROR - Error in step initialize_database: Database creation failed
Traceback (most recent call last):
  File "C:\Users\mmenaarx\Project_AI_CoE\ai-demo-sync-utils-main\main.py", line 116, in wrapper
    result = func(self, *args, **kwargs)
             ^^^^^^^^^^^^^^^^^^^^^^^^^^^
  File "C:\Users\mmenaarx\Project_AI_CoE\ai-demo-sync-utils-main\main.py", line 134, in initialize_database
    raise Exception("Database creation failed")
Exception: Database creation failed
2024-10-29 18:27:09,208 - ERROR - Pipeline failed with error:
Traceback (most recent call last):
  File "C:\Users\mmenaarx\Project_AI_CoE\ai-demo-sync-utils-main\main.py", line 185, in run_pipeline
    self.initialize_database()
  File "C:\Users\mmenaarx\Project_AI_CoE\ai-demo-sync-utils-main\main.py", line 116, in wrapper
    result = func(self, *args, **kwargs)
             ^^^^^^^^^^^^^^^^^^^^^^^^^^^
  File "C:\Users\mmenaarx\Project_AI_CoE\ai-demo-sync-utils-main\main.py", line 134, in initialize_database
    raise Exception("Database creation failed")
Exception: Database creation failed
2024-10-29 18:27:09,208 - ERROR - Pipeline execution failed
Traceback (most recent call last):
  File "C:\Users\mmenaarx\Project_AI_CoE\ai-demo-sync-utils-main\main.py", line 205, in <module>
    pipeline.run_pipeline()
  File "C:\Users\mmenaarx\Project_AI_CoE\ai-demo-sync-utils-main\main.py", line 185, in run_pipeline
    self.initialize_database()
  File "C:\Users\mmenaarx\Project_AI_CoE\ai-demo-sync-utils-main\main.py", line 116, in wrapper
    result = func(self, *args, **kwargs)
             ^^^^^^^^^^^^^^^^^^^^^^^^^^^
  File "C:\Users\mmenaarx\Project_AI_CoE\ai-demo-sync-utils-main\main.py", line 134, in initialize_database
    raise Exception("Database creation failed")
Exception: Database creation failed
